Workbook

Sheet start
B1: Автоматизация создания ТТН
B3: Данные: | C3: Лист data
B4: Шаблон: | C4: Лист template
B11: Создано: | C11: 10
B12: Последний запуск: | C12: 46180.614

Sheet data
A1: исходные данные | C1: данные для вставки
A2: На главную | D2: 2 | E2: 3 | F2: 4 | G2: 5 | H2: 6 | I2: 7 | J2: 8 | K2: 9 | L2: 10 | M2: 11 | N2: 12 | O2: 13 | P2: 14 | Q2: 15 | R2: 16 | S2: 17 | T2: 18 | U2: 19 | V2: 20 | W2: 21 | X2: 22 | Y2: 23 | Z2: 24 | AA2: 25 | AB2: 26
A3: дата | B3: авто | C3: id | D3: номер | E3: день | F3: месяц | G3: год | H3: организация | I3: марка_авто | J3: гос_номер-авто | K3: орг_владелец_авто | L3: водитель_фио | M3: заказчик | N3: грузоотправитель | O3: пункт_погрузки | P3: грузополучатель | Q3: пункт_разгрузки | R3: прицеп_гос_номер | S3: продукция | T3: брутто | U3: тара | V3: нетто | W3: отпустил_должность | X3: отпустил_фио | Y3: сдал_должность | Z3: сдал_фио | AA3: принял_фио_сокр | AB3: приложение
A4: 45915 | B4: КАМАЗ О975ВВ761 СК214461 | C4: 1 | D4: 9512 | E4: =DAY(A4) -> 15 | F4: =CHOOSE(MONTH(A4),"января","февраля","марта","апреля","мая","июня","июля","августа","сентября","октября","ноября","декабря") -> сентября | G4: =MOD(YEAR(A4),100) -> 25 | H4: ООО "АгроФлоу X1" | I4: =LEFT(B4,FIND(" ",B4)-1) -> КАМАЗ | J4: =MID(B4,FIND(" ",B4)+1,FIND(" ",B4,FIND(" ",B4)+1)-FIND(" ",B4)-1) -> О975ВВ761 | K4: ООО "ТрансВектор X1" | L4: Иванор Сергей Петрович | M4: =H4 -> ООО "АгроФлоу X1" | N4: ООО "АгроЭкспорт X9" | O4: Краснодарский край | P4: =H4 -> ООО "АгроФлоу X1" | Q4: Ростовская обл. | R4: =MID(B4,FIND(" ",B4,FIND(" ",B4)+1)+1,LEN(B4)-FIND(" ",B4,FIND(" ",B4)+1)) -> СК214461 | S4: пшеница 3 класса | T4: 34600 | U4: 15220 | V4: 19380 | W4: директор | X4: Таргин Алексей Викторович | Y4: кладовщик | Z4: Сидорина М.А. | AA4: =LEFT(L4,FIND(" ",L4)-1) & " " & MID(L4,FIND(" ",L4)+1,1) & "." & MID(L4,FIND(" ",L4,FIND(" ",L4)+1)+1,1) & "." -> Иванор С.П. | AB4: Декларация соответствия
A5: 45915 | B5: МАЗ А123МР777 ВЕ547391 | C5: 2 | D5: 9513 | E5: =DAY(A5) -> 15 | F5: =CHOOSE(MONTH(A5),"января","февраля","марта","апреля","мая","июня","июля","августа","сентября","октября","ноября","декабря") -> сентября | G5: =MOD(YEAR(A5),100) -> 25 | H5: ООО "ЗерноПриём 24A" | I5: =LEFT(B5,FIND(" ",B5)-1) -> МАЗ | J5: =MID(B5,FIND(" ",B5)+1,FIND(" ",B5,FIND(" ",B5)+1)-FIND(" ",B5)-1) -> А123МР777 | K5: ООО "ГрузЛогистика 14A" | L5: Смирев Андрей Николаевич | M5: =H5 -> ООО "ЗерноПриём 24A" | N5: ООО "ЗерноОтгрузка 21A" | O5: Краснодарский край | P5: =H5 -> ООО "ЗерноПриём 24A" | Q5: Ростовская обл. | R5: ВЕ547391 | S5: пшеница 3 класса | T5: 35120 | U5: 14850 | V5: 20270 | W5: директор | X5: Лемиров Сергей Андреевич | Y5: кладовщик | Z5: Петровина О.С. | AA5: =LEFT(L5,FIND(" ",L5)-1) & " " & MID(L5,FIND(" ",L5)+1,1) & "." & MID(L5,FIND(" ",L5,FIND(" ",L5)+1)+1,1) & "." -> Смирев А.Н. | AB5: Декларация соответствия
A6: 45915 | B6: Мерседес М456ЕХ163 РТ932854 | C6: 3 | D6: 9514 | E6: =DAY(A6) -> 15 | F6: =CHOOSE(MONTH(A6),"января","февраля","марта","апреля","мая","июня","июля","августа","сентября","октября","ноября","декабря") -> сентября | G6: =MOD(YEAR(A6),100) -> 25 | H6: ООО "ГрейнПорт-Х" | I6: =LEFT(B6,FIND(" ",B6)-1) -> Мерседес | J6: =MID(B6,FIND(" ",B6)+1,FIND(" ",B6,FIND(" ",B6)+1)-FIND(" ",B6)-1) -> М456ЕХ163 | K6: ООО "АвтоЗерноПоток-Х" | L6: Кузнецын Алексей Викторович | M6: =H6 -> ООО "ГрейнПорт-Х" | N6: ООО "ТрансАгроЛиния-Х" | O6: Краснодарский край | P6: =H6 -> ООО "ГрейнПорт-Х" | Q6: Ростовская обл. | R6: РТ932854 | S6: пшеница | T6: 33890 | U6: 15640 | V6: 18250 | W6: директор | X6: Неворин Дмитрий Олегович | Y6: кладовщик | Z6: Калинина Н.В. | AA6: =LEFT(L6,FIND(" ",L6)-1) & " " & MID(L6,FIND(" ",L6)+1,1) & "." & MID(L6,FIND(" ",L6,FIND(" ",L6)+1)+1,1) & "." -> Кузнецын А.В. | AB6: Декларация соответствия
A7: 45950 | B7: КАМАЗ Т789АН402 МН678912 | C7: 4 | D7: 9515 | E7: =DAY(A7) -> 20 | F7: =CHOOSE(MONTH(A7),"января","февраля","марта","апреля","мая","июня","июля","августа","сентября","октября","ноября","декабря") -> октября | G7: =MOD(YEAR(A7),100) -> 25 | H7: ООО "АгроЛогистик Z7" | I7: =LEFT(B7,FIND(" ",B7)-1) -> КАМАЗ | J7: =MID(B7,FIND(" ",B7)+1,FIND(" ",B7,FIND(" ",B7)+1)-FIND(" ",B7)-1) -> Т789АН402 | K7: ООО "ЮгТрансСистема Q3" | L7: Попович Денис Олегович | M7: =H7 -> ООО "АгроЛогистик Z7" | N7: ООО "ЮгПоставка Q8" | O7: Ставропольский край | P7: =H7 -> ООО "АгроЛогистик Z7" | Q7: Ростовская обл. | R7: МН678912 | S7: ячмень | T7: 35980 | U7: 14320 | V7: 21660 | W7: директор | X7: Заревский Павел Николаевич | Y7: кладовщик | Z7: Горина Е.А. | AA7: =LEFT(L7,FIND(" ",L7)-1) & " " & MID(L7,FIND(" ",L7)+1,1) & "." & MID(L7,FIND(" ",L7,FIND(" ",L7)+1)+1,1) & "." -> Попович Д.О. | AB7: Декларация соответствия
A8: 45951 | B8: КАМАЗ В321ОО599 АП456782 | C8: 5 | D8: 9516 | E8: =DAY(A8) -> 21 | F8: =CHOOSE(MONTH(A8),"января","февраля","марта","апреля","мая","июня","июля","августа","сентября","октября","ноября","декабря") -> октября | G8: =MOD(YEAR(A8),100) -> 25 | H8: ООО "ЮгЗерноСнаб X2" | I8: =LEFT(B8,FIND(" ",B8)-1) -> КАМАЗ | J8: =MID(B8,FIND(" ",B8)+1,FIND(" ",B8,FIND(" ",B8)+1)-FIND(" ",B8)-1) -> В321ОО599 | K8: ООО "ГрейнТрансЛайн X8" | L8: Моргин Павел Сергеевич | M8: =H8 -> ООО "ЮгЗерноСнаб X2" | N8: ООО "ГрейнСинтез 3X" | O8: Ставропольский край | P8: =H8 -> ООО "ЮгЗерноСнаб X2" | Q8: Ростовская обл. | R8: АП456782 | S8: ячмень | T8: 32750 | U8: 15910 | V8: 16840 | W8: директор | X8: Волягин Егор Дмитриевич | Y8: кладовщик | Z8: Таревская И.О. | AA8: =LEFT(L8,FIND(" ",L8)-1) & " " & MID(L8,FIND(" ",L8)+1,1) & "." & MID(L8,FIND(" ",L8,FIND(" ",L8)+1)+1,1) & "." -> Моргин П.С. | AB8: Декларация соответствия
A9: 45952 | B9: МАЗ К654РМ750 ЕС327109 | C9: 6 | D9: 9517 | E9: =DAY(A9) -> 22 | F9: =CHOOSE(MONTH(A9),"января","февраля","марта","апреля","мая","июня","июля","августа","сентября","октября","ноября","декабря") -> октября | G9: =MOD(YEAR(A9),100) -> 25 | H9: ООО "ПотокАгро Q1" | I9: =LEFT(B9,FIND(" ",B9)-1) -> МАЗ | J9: =MID(B9,FIND(" ",B9)+1,FIND(" ",B9,FIND(" ",B9)+1)-FIND(" ",B9)-1) -> К654РМ750 | K9: ООО "АгроАвтоСинтез 6B" | L9: Калевин Денис Игоревич | M9: =H9 -> ООО "ПотокАгро Q1" | N9: ООО "АгроВектор Z2" | O9: Ставропольский край | P9: =H9 -> ООО "ПотокАгро Q1" | Q9: Ростовская обл. | R9: ЕС327109 | S9: пшеница | T9: 34410 | U9: 15180 | V9: 19230 | W9: директор | X9: Крестовин Роман Алексеевич | Y9: кладовщик | Z9: Карпелин М.А. | AA9: =LEFT(L9,FIND(" ",L9)-1) & " " & MID(L9,FIND(" ",L9)+1,1) & "." & MID(L9,FIND(" ",L9,FIND(" ",L9)+1)+1,1) & "." -> Калевин Д.И. | AB9: Декларация соответствия
A10: 46000 | B10: Мерседес Н987НН222 ТР894567 | C10: 7 | D10: 9518 | E10: =DAY(A10) -> 9 | F10: =CHOOSE(MONTH(A10),"января","февраля","марта","апреля","мая","июня","июля","августа","сентября","октября","ноября","декабря") -> декабря | G10: =MOD(YEAR(A10),100) -> 25 | H10: ООО "ТерраГрейн 9X" | I10: =LEFT(B10,FIND(" ",B10)-1) -> Мерседес | J10: =MID(B10,FIND(" ",B10)+1,FIND(" ",B10,FIND(" ",B10)+1)-FIND(" ",B10)-1) -> Н987НН222 | K10: ООО "ДорТрансАгро X2" | L10: Родевский Андрей Николаевич | M10: =H10 -> ООО "ТерраГрейн 9X" | N10: ООО "ПоляТрейд X5" | O10: Краснодарский край | P10: =H10 -> ООО "ТерраГрейн 9X" | Q10: Ростовская обл. | R10: ТР894567 | S10: пшеница | T10: 35560 | U10: 14790 | V10: 20770 | W10: директор | X10: Орлинов Виктор Павлович | Y10: кладовщик | Z10: Новаров П.Н. | AA10: =LEFT(L10,FIND(" ",L10)-1) & " " & MID(L10,FIND(" ",L10)+1,1) & "." & MID(L10,FIND(" ",L10,FIND(" ",L10)+1)+1,1) & "." -> Родевский А.Н. | AB10: Декларация соответствия
A11: 46045 | B11: Вольво С246ЕТ888 ОК213478 | C11: 8 | D11: 9519 | E11: =DAY(A11) -> 23 | F11: =CHOOSE(MONTH(A11),"января","февраля","марта","апреля","мая","июня","июля","августа","сентября","октября","ноября","декабря") -> января | G11: =MOD(YEAR(A11),100) -> 26 | H11: ООО "ФермаТрейд-Х" | I11: =LEFT(B11,FIND(" ",B11)-1) -> Вольво | J11: =MID(B11,FIND(" ",B11)+1,FIND(" ",B11,FIND(" ",B11)+1)-FIND(" ",B11)-1) -> С246ЕТ888 | K11: ООО "ЛогистикФлоу 19X" | L11: Семиров Артём Викторович | M11: =H11 -> ООО "ФермаТрейд-Х" | N11: ООО "ЗерноЛайн-24B" | O11: Краснодарский край | P11: =H11 -> ООО "ФермаТрейд-Х" | Q11: Ростовская обл. | R11: ОК213478 | S11: кукуруза | T11: 33280 | U11: 15460 | V11: 17820 | W11: директор | X11: Белярев Кирилл Сергеевич | Y11: кладовщик | Z11: Сольцев А.В. | AA11: =LEFT(L11,FIND(" ",L11)-1) & " " & MID(L11,FIND(" ",L11)+1,1) & "." & MID(L11,FIND(" ",L11,FIND(" ",L11)+1)+1,1) & "." -> Семиров А.В. | AB11: Декларация соответствия
A12: 46083 | B12: Вольво Р135РТ311 КМ765981 | C12: 9 | D12: 9520 | E12: =DAY(A12) -> 2 | F12: =CHOOSE(MONTH(A12),"января","февраля","марта","апреля","мая","июня","июля","августа","сентября","октября","ноября","декабря") -> марта | G12: =MOD(YEAR(A12),100) -> 26 | H12: ООО "ЗерноХаб 17B" | I12: =LEFT(B12,FIND(" ",B12)-1) -> Вольво | J12: =MID(B12,FIND(" ",B12)+1,FIND(" ",B12,FIND(" ",B12)+1)-FIND(" ",B12)-1) -> Р135РТ311 | K12: ООО "ЗерноМобиль V4" | L12: Горевин Максим Олегович | M12: =H12 -> ООО "ЗерноХаб 17B" | N12: ООО "ФлоуАгро V1" | O12: Краснодарский край | P12: =H12 -> ООО "ЗерноХаб 17B" | Q12: Ростовская обл. | R12: КМ765981 | S12: кукуруза | T12: 34870 | U12: 14950 | V12: 19920 | W12: директор | X12: Снегиров Андрей Олегович | Y12: кладовщик | Z12: Ардентов И.С. | AA12: =LEFT(L12,FIND(" ",L12)-1) & " " & MID(L12,FIND(" ",L12)+1,1) & "." & MID(L12,FIND(" ",L12,FIND(" ",L12)+1)+1,1) & "." -> Горевин М.О. | AB12: Декларация соответствия
A13: 46180 | B13: КАМАЗ У864УН049 СХ432156 | C13: 10 | D13: 9521 | E13: =DAY(A13) -> 7 | F13: =CHOOSE(MONTH(A13),"января","февраля","марта","апреля","мая","июня","июля","августа","сентября","октября","ноября","декабря") -> июня | G13: =MOD(YEAR(A13),100) -> 26 | H13: ООО "АгроСклад V3" | I13: =LEFT(B13,FIND(" ",B13)-1) -> КАМАЗ | J13: =MID(B13,FIND(" ",B13)+1,FIND(" ",B13,FIND(" ",B13)+1)-FIND(" ",B13)-1) -> У864УН049 | K13: ООО "ТрансЮгЭкспресс X9" | L13: Даневский Кирилл Андреевич | M13: =H13 -> ООО "АгроСклад V3" | N13: ООО "АгроТерминал X7" | O13: Краснодарский край | P13: =H13 -> ООО "АгроСклад V3" | Q13: Ростовская обл. | R13: СХ432156 | S13: пшеница | T13: 36240 | U13: 14130 | V13: 22110 | W13: директор | X13: Ветровин Денис Игоревич | Y13: кладовщик | Z13: Родина В.А. | AA13: =LEFT(L13,FIND(" ",L13)-1) & " " & MID(L13,FIND(" ",L13)+1,1) & "." & MID(L13,FIND(" ",L13,FIND(" ",L13)+1)+1,1) & "." -> Даневский К.А. | AB13: Декларация соответствия

Sheet template
DD1: Типовая межотраслевая форма № СП-31 | DE1: 1
DE2: На главную
BS3: ТОВАРНО-ТРАНСПОРТНАЯ НАКЛАДНАЯ (зерно) № | BT3: =IFERROR(INDEX(data!C:AB, MATCH($DE$1, data!C:C, 0), data!D2), "") -> 9512 | CS3: Коды | DE3: Лист data
AH4: " | AI4: =IFERROR(INDEX(data!C:AB, MATCH($DE$1, data!C:C, 0), data!E2), "") -> 15 | AM4: " | AO4: =IFERROR(INDEX(data!C:AB, MATCH($DE$1, data!C:C, 0), data!F2), "") -> сентября | BA4: 20 | BE4: =IFERROR(INDEX(data!C:AB, MATCH($DE$1, data!C:C, 0), data!G2), "") -> 25 | BI4: г. | CP4: Форма по ОКУД | CS4: 0325031
CP5: Дата составления
B6: Организация | N6: =IFERROR(INDEX(data!C:AB, MATCH($DE$1, data!C:C, 0), data!H2), "") -> ООО "АгроФлоу X1" | CP6: по ОКПО
B7: Марка автомобиля | S7: =IFERROR(INDEX(data!C:AB, MATCH($DE$1, data!C:C, 0), data!I2), "") -> КАМАЗ | AH7: Государственный номерной знак | BK7: =IFERROR(INDEX(data!C:AB, MATCH($DE$1, data!C:C, 0), data!J2), "") -> О975ВВ761 | CP7: к путевому листу №
B9: Организация-владелец автотранспорта | AJ9: =IFERROR(INDEX(data!C:AB, MATCH($DE$1, data!C:C, 0), data!K2), "") -> ООО "ТрансВектор X1"
AJ10: (наименование, адрес, номер телефона)
B11: Водитель | K11: =IFERROR(INDEX(data!C:AB, MATCH($DE$1, data!C:C, 0), data!L2), "") -> Иванор Сергей Петрович | BC11: коммерческая
B12: Заказчик | K12: (фамилия, имя, отчество) | BC12: (вид перевозки)
B13: (плательщик) | O13: =IFERROR(INDEX(data!C:AB, MATCH($DE$1, data!C:C, 0), data!M2), "") -> ООО "АгроФлоу X1"
O14: (наименование, адрес, номер телефона)
B15: Грузоот-
B16: правитель | L16: =IFERROR(INDEX(data!C:AB, MATCH($DE$1, data!C:C, 0), data!N2), "") -> ООО "АгроЭкспорт X9"
B17: Пункт | L17: (наименование, адрес, номер телефона)
B18: погрузки | L18: =IFERROR(INDEX(data!C:AB, MATCH($DE$1, data!C:C, 0), data!O2), "") -> Краснодарский край | BU18: Отделение (цех), бригада, звено
L19: (адрес)
B21: Грузополучатель | R21: =IFERROR(INDEX(data!C:AB, MATCH($DE$1, data!C:C, 0), data!P2), "") -> ООО "АгроФлоу X1"
R22: (наименование, адрес, номер телефона)
B23: Пункт | L23: =IFERROR(INDEX(data!C:AB, MATCH($DE$1, data!C:C, 0), data!Q2), "") -> Ростовская обл.
B24: разгрузки | CN24: Маршрут №
L25: (адрес)
M27: Прицеп: Государственный номерной знак | AY27: =IFERROR(INDEX(data!C:AB, MATCH($DE$1, data!C:C, 0), data!R2), "") -> СК214461 | CN27: Гаражный номер
M29: Сведения о грузе | AG29: Счет (дебет) | CA29: Счет (кредит)
B33: Продукция | M33: =IFERROR(INDEX(data!C:AB, MATCH($DE$1, data!C:C, 0), data!S2), "") -> пшеница 3 класса
M34: (наименование зерновых и масляничных культур, семян, трав)
B35: Сорт, класс | AI35: Засоренность | BO35: % | BT35: Влажность | CX35: %
A37: Операция | U37: Вид упа- ковки | AB37: Коли- чество | AK37: Класс груза | AS37: Масса, кг | BT37: Цена, руб. коп. | CJ37: Сумма, руб. коп.
AS38: брутто | BB38: тара | BK38: нетто
U40: 1 | AB40: 2 | AK40: 3 | AS40: 4 | BB40: 5 | BK40: 6 | BT40: 7 | CJ40: 8
F41: Отправлено | U41: навалом | AB41: 1 | AS41: =IFERROR(INDEX(data!C:AB, MATCH($DE$1, data!C:C, 0), data!T2), "") -> 34600 | BB41: =IFERROR(INDEX(data!C:AB, MATCH($DE$1, data!C:C, 0), data!U2), "") -> 15220 | BK41: =IFERROR(INDEX(data!C:AB, MATCH($DE$1, data!C:C, 0), data!V2), "") -> 19380
F42: Принято | U42: навалом | AB42: 1 | AK42: Х
U44: За ценные сорта | AI44: За сортировку и упаковку | AX44: За тару | BG44: За доставку продукции | BR44: Прочие доплаты | CC44: Всего к оплате
U46: 9 | AI46: 10 | AX46: 11 | BG46: 12 | BR46: 13 | CC46: 14
B47: Надбавки - руб. коп.
B49: Сумма к | BY49: Счет (дебет)
B50: оплате
J51: (прописью)
BY52: Счет (кредит)
...
